‚úÖ Job started at: Sun May  4 12:50:19 CEST 2025
Lmod has detected the following error: The following module(s) are unknown:
"python/3.9"

Please check the spelling or version number. Also try "module spider ..."
It is also possible your cache file is out-of-date; it may help to try:
  $ module --ignore_cache load "python/3.9"

Also make sure that all modulefiles written in TCL start with the string
#%Module



üì¶ Ensuring 'requests' is installed...
Requirement already satisfied: requests in /usr/lib/python3.9/site-packages (2.25.1)
Requirement already satisfied: chardet<5,>=3.0.2 in /usr/lib/python3.9/site-packages (from requests) (4.0.0)
Requirement already satisfied: urllib3<1.27,>=1.21.1 in /usr/lib/python3.9/site-packages (from requests) (1.26.5)
Requirement already satisfied: idna<3,>=2.5 in /usr/lib/python3.9/site-packages (from requests) (2.10)
WARNING: Value for scheme.platlib does not match. Please report this to <https://github.com/pypa/pip/issues/10151>
distutils: /home/pnair/.local/lib/python3.9/site-packages
sysconfig: /home/pnair/.local/lib64/python3.9/site-packages
WARNING: Additional context:
user = True
home = None
root = None
prefix = None
‚¨áÔ∏è Downloading the entire dataset...
Traceback (most recent call last):
  File "/gpfs/scratch1/shared/dl2_spai/datasets/LSUN/lsun/download.py", line 59, in <module>
    main()
  File "/gpfs/scratch1/shared/dl2_spai/datasets/LSUN/lsun/download.py", line 41, in main
    categories = list_categories()
  File "/gpfs/scratch1/shared/dl2_spai/datasets/LSUN/lsun/download.py", line 17, in list_categories
    with urlopen(Request(url)) as response:
  File "/usr/lib64/python3.9/urllib/request.py", line 214, in urlopen
    return opener.open(url, data, timeout)
  File "/usr/lib64/python3.9/urllib/request.py", line 523, in open
    response = meth(req, response)
  File "/usr/lib64/python3.9/urllib/request.py", line 632, in http_response
    response = self.parent.error(
  File "/usr/lib64/python3.9/urllib/request.py", line 561, in error
    return self._call_chain(*args)
  File "/usr/lib64/python3.9/urllib/request.py", line 494, in _call_chain
    result = func(*args)
  File "/usr/lib64/python3.9/urllib/request.py", line 641, in http_error_default
    raise HTTPError(req.full_url, code, msg, hdrs, fp)
urllib.error.HTTPError: HTTP Error 404: Not Found
‚¨áÔ∏è Downloading 'test' set...
Traceback (most recent call last):
  File "/gpfs/scratch1/shared/dl2_spai/datasets/LSUN/lsun/download.py", line 59, in <module>
    main()
  File "/gpfs/scratch1/shared/dl2_spai/datasets/LSUN/lsun/download.py", line 41, in main
    categories = list_categories()
  File "/gpfs/scratch1/shared/dl2_spai/datasets/LSUN/lsun/download.py", line 17, in list_categories
    with urlopen(Request(url)) as response:
  File "/usr/lib64/python3.9/urllib/request.py", line 214, in urlopen
    return opener.open(url, data, timeout)
  File "/usr/lib64/python3.9/urllib/request.py", line 523, in open
    response = meth(req, response)
  File "/usr/lib64/python3.9/urllib/request.py", line 632, in http_response
    response = self.parent.error(
  File "/usr/lib64/python3.9/urllib/request.py", line 561, in error
    return self._call_chain(*args)
  File "/usr/lib64/python3.9/urllib/request.py", line 494, in _call_chain
    result = func(*args)
  File "/usr/lib64/python3.9/urllib/request.py", line 641, in http_error_default
    raise HTTPError(req.full_url, code, msg, hdrs, fp)
urllib.error.HTTPError: HTTP Error 404: Not Found
‚úÖ All downloads complete at: Sun May  4 12:50:25 CEST 2025

JOB STATISTICS
==============
Job ID: 11558859
Cluster: snellius
User/Group: pnair/pnair
State: RUNNING
Nodes: 1
Cores per node: 32
CPU Utilized: 00:00:00
CPU Efficiency: 0.00% of 00:06:56 core-walltime
Job Wall-clock time: 00:00:13
Memory Utilized: 0.00 MB
Memory Efficiency: 0.00% of 8.00 GB (8.00 GB/node)
WARNING: Efficiency statistics can only be obtained after the job has ended as seff tool is based on the accounting database data.
